Workbook
Name MY_FUNCTION2: LAMBDA(IF(OR(ISBLANK(EDA!$F$3), EDA!$F$3=0), AVERAGEIF(EDA!$F$3:$F$601, ">0"), EDA!$F$3))
Name MY_FUNCTION1: LAMBDA(IF(ISBLANK(EDA!$F$3),AVERAGE(EDA!$F$3:$F$601),EDA!$F$3))

Sheet Raw Data
A1: student_id | B1: course_id | C1: enroll_date | D1: completion_date | E1: course_category | F1: course_rating | G1: progress_percent | H1: completed | I1: hours_spent | J1: country | K1: device | L1: retained_after_30d
A2: cce730c3-9ef3-4908-98fd-9bbd3cf0f581 | B2: c3646abb-6357-4ff9-888d-44307ebc13de | C2: 45115 | D2: 45127 | E2: Design | F2: 0.2 | G2: 14 | H2: 0 | I2: 30 | J2: Germany | K2: Tablet | L2: 1 | N2: =COUNTA(A:A) -> 601
A3: 1c8eee56-baa9-41bd-8631-178c4e031945 | B3: 95a9248a-784c-4e23-ab91-2d50c8166c68 | C3: 45079 | D3: 45091 | E3: Design | F3: 2 | G3: 32 | H3: 0 | I3: 48 | J3: UK | K3: Tablet | L3: 1
A4: 3b698e92-f0b7-45c1-98f8-c5059e58adad | B4: d745141a-a0be-4ac0-810e-692097da03ce | C4: 45028 | D4: 45040 | E4: Business | F4: 0.3 | G4: 16 | H4: 1 | I4: 34 | J4: France | K4: Tablet | L4: 0
A5: d9466dbd-2174-4f99-8c1a-8c6c01c5887c | B5: 22bb11df-c89a-49f5-be9b-0caf2704f618 | C5: 45031 | D5: 45043 | E5: Design | F5: 3.3 | G5: 78 | H5: 1 | I5: 39 | J5: Germany | K5: Mobile | L5: 0
A6: 1bea3447-5bea-41c7-ab4d-f986e6fde451 | B6: 1a77e025-2a7b-4805-a5c5-0188d77a7525 | C6: 45107 | D6: 45119 | E6: Data Science | F6: 0.6 | G6: 36 | H6: 0 | I6: 40 | J6: Germany | K6: Mobile | L6: 0
A7: 289a8ea6-642e-4b99-8fd3-3636bcfff1d5 | B7: 333a070a-b557-4b2e-af6a-91a96ef7371a | C7: 44980 | D7: 44992 | E7: Design | F7: 3 | G7: 81 | H7: 0 | I7: 44 | J7: USA | K7: Mobile | L7: 1
A8: bab505e1-4553-46f6-bc5b-a1f3a7578204 | B8: f695765c-a26f-400a-ba3a-a285ffee86ae | C8: 45281 | D8: 45293 | E8: Business | F8: 3.6 | G8: 57 | H8: 1 | I8: 25 | J8: India | K8: Mobile | L8: 1
A9: 2ea71ca3-dcc9-4308-aa6a-9dd40e633410 | B9: 1372c380-c140-441c-b635-8066e5d151bc | C9: 45088 | D9: 45100 | E9: Marketing | F9: 0.5 | G9: 11 | H9: 0 | I9: 43 | J9: UK | K9: Mobile | L9: 1
A10: 6687893e-b67b-44a7-8b91-8a1597d6ac6e | B10: 52d57a77-4a92-44b5-ad65-767a55d591cb | C10: 45068 | D10: 45080 | E10: Marketing | F10: 4.7 | G10: 76 | H10: 1 | I10: 17 | J10: USA | K10: Mobile | L10: 1
A11: 5209afee-c45c-4646-bc03-aa6b4e728b5c | B11: 88262933-ca7c-4fb9-b1f1-769142d77788 | C11: 44939 | D11: 44951 | E11: Marketing | F11: 4.4 | G11: 49 | H11: 1 | I11: 31 | J11: France | K11: Tablet | L11: 0
A12: ffa30b8e-fc9b-45d5-beb4-90941141d853 | B12: d2d92ae0-0131-4401-a893-2907767aabdb | C12: 45128 | D12: 45140 | E12: Marketing | F12: 2.6 | G12: 5 | H12: 0 | I12: 35 | J12: India | K12: Tablet | L12: 1
A13: 373def54-c256-4f5a-8cf5-f57bff0152c2 | B13: 5b3d4dca-0197-4560-a54f-4179c5b0b029 | C13: 45212 | D13: 45224 | E13: Marketing | F13: 0.8 | G13: 2 | H13: 1 | I13: 36 | J13: UK | K13: Desktop | L13: 0
A14: e5343efa-051f-4846-881b-7c410937b7d1 | B14: 18020988-974c-40b3-94e9-74068bf8d6f2 | C14: 45195 | D14: 45207 | E14: Marketing | F14: 0.1 | G14: 8 | H14: 1 | I14: 15 | J14: Germany | K14: Mobile | L14: 0
... A600: 9a0c3761-f5f8-439a-9ffb-1b5502aeee23 | B600: 26ec6488-6474-44a6-96fa-34078b6f3b7f | C600: 45166 | D600: 45178 | E600: Business | F600: 2.6 | G600: 41 | H600: 1 | I600: 41 | J600: Germany | K600: Desktop | L600: 1
A601: 437a83a1-662f-4cb0-892b-984c6530ab46 | B601: e38f488a-2fb5-4509-b761-c2a1df5af133 | C601: 45157 | D601: 45169 | E601: Design | F601: 1.7 | H601: 0 | I601: 48 | J601: UK | K601: Mobile | L601: 1

Sheet EDA
A1: EDA — дослідницький аналіз даних: очищення, типізація, пошук аномалій, побудова первинних графіків
A2: {={"string","string","date","date","text","number","number","boolean","number","text","text","boolean"}} -> string | B2: string | C2: date | D2: date | E2: text | F2: number | G2: number | H2: boolean | I2: number | J2: text | K2: text | L2: boolean | M2: text | N2: =IF(ISBLANK(F2),AVERAGE(F$4:F$601),F2) -> number
A3: {='Raw Data'!A1:L601} -> student_id | B3: course_id | C3: enroll_date | D3: completion_date | E3: course_category | F3: course_rating | G3: progress_percent | H3: completed | I3: hours_spent | J3: country | K3: device | L3: retained_after_30d | M3: missing_check | N3: =IF(ISBLANK(F3),AVERAGE(F$4:F$601),F3) -> course_rating
A4: cce730c3-9ef3-4908-98fd-9bbd3cf0f581 | B4: c3646abb-6357-4ff9-888d-44307ebc13de | C4: 45115 | D4: 45127 | E4: Design | F4: 0.2 | G4: 14 | H4: 0 | I4: 30 | J4: Germany | K4: Tablet | L4: 1 | M4: =IF(COUNTA(A3:L3)<12,"Missing","OK") -> OK | N4: =IF(ISBLANK(F4),AVERAGE(F$4:F$603),F4:F1000) -> 0.2 | R4: Середній рейтинг курсів за категоріями | U4: Розподіл користувачів за пристроями
A5: 1c8eee56-baa9-41bd-8631-178c4e031945 | B5: 95a9248a-784c-4e23-ab91-2d50c8166c68 | C5: 45079 | D5: 45091 | E5: Design | F5: 2 | G5: 32 | H5: 0 | I5: 48 | J5: UK | K5: Tablet | L5: 1 | M5: =IF(COUNTA(A4:L4)<12,"Missing","OK") -> OK | N5: =IF(ISBLANK(F5),AVERAGE(F$4:F$601),F5:F1000) -> 2 | R5: =IFERROR(__xludf.DUMMYFUNCTION("QUERY(A3:L1000, ""select E, avg(F) where E is not null and E <> '0' and E <> '' group by E order by avg(F) desc label avg(F) 'avg_rating'"", 1)"),"course_category") -> course_category | S5: =IFERROR(__xludf.DUMMYFUNCTION("""COMPUTED_VALUE"""),"avg_rating") -> avg_rating | U5: =IFERROR(__xludf.DUMMYFUNCTION("QUERY(A3:L1000, ""select K, count(A) where K is not null and K <> '0' and K <> '' group by K order by count(A) desc label count(A) 'users'"", 1)"),"device") -> device | V5: =IFERROR(__xludf.DUMMYFUNCTION("""COMPUTED_VALUE"""),"users") -> users
A6: 3b698e92-f0b7-45c1-98f8-c5059e58adad | B6: d745141a-a0be-4ac0-810e-692097da03ce | C6: 45028 | D6: 45040 | E6: Business | F6: 0.3 | G6: 16 | H6: 1 | I6: 34 | J6: France | K6: Tablet | L6: 0 | M6: =IF(COUNTA(A5:L5)<12,"Missing","OK") -> OK | N6: =IF(ISBLANK(F6),AVERAGE(F$4:F$601),F6:F1001) -> 0.3 | R6: =IFERROR(__xludf.DUMMYFUNCTION("""COMPUTED_VALUE"""),"Business") -> Business | S6: =IFERROR(__xludf.DUMMYFUNCTION("""COMPUTED_VALUE"""),2.698581560283688) -> 2.6985816 | U6: =IFERROR(__xludf.DUMMYFUNCTION("""COMPUTED_VALUE"""),"Tablet") -> Tablet | V6: =IFERROR(__xludf.DUMMYFUNCTION("""COMPUTED_VALUE"""),220.0) -> 220
A7: d9466dbd-2174-4f99-8c1a-8c6c01c5887c | B7: 22bb11df-c89a-49f5-be9b-0caf2704f618 | C7: 45031 | D7: 45043 | E7: Design | F7: 3.3 | G7: 78 | H7: 1 | I7: 39 | J7: Germany | K7: Mobile | L7: 0 | M7: =IF(COUNTA(A6:L6)<12,"Missing","OK") -> OK | N7: =IF(ISBLANK(F7),AVERAGE(F$4:F$601),F7:F1002) -> 3.3 | R7: =IFERROR(__xludf.DUMMYFUNCTION("""COMPUTED_VALUE"""),"Data Science") -> Data Science | S7: =IFERROR(__xludf.DUMMYFUNCTION("""COMPUTED_VALUE"""),2.6318181818181814) -> 2.6318182 | U7: =IFERROR(__xludf.DUMMYFUNCTION("""COMPUTED_VALUE"""),"Mobile") -> Mobile | V7: =IFERROR(__xludf.DUMMYFUNCTION("""COMPUTED_VALUE"""),201.0) -> 201
A8: 1bea3447-5bea-41c7-ab4d-f986e6fde451 | B8: 1a77e025-2a7b-4805-a5c5-0188d77a7525 | C8: 45107 | D8: 45119 | E8: Data Science | F8: 0.6 | G8: 36 | H8: 0 | I8: 40 | J8: Germany | K8: Mobile | L8: 0 | M8: =IF(COUNTA(A7:L7)<12,"Missing","OK") -> OK | N8: =IF(ISBLANK(F8),AVERAGE(F$4:F$601),F8:F1003) -> 0.6 | R8: =IFERROR(__xludf.DUMMYFUNCTION("""COMPUTED_VALUE"""),"Design") -> Design | S8: =IFERROR(__xludf.DUMMYFUNCTION("""COMPUTED_VALUE"""),2.430921052631579) -> 2.4309211 | U8: =IFERROR(__xludf.DUMMYFUNCTION("""COMPUTED_VALUE"""),"Desktop") -> Desktop | V8: =IFERROR(__xludf.DUMMYFUNCTION("""COMPUTED_VALUE"""),179.0) -> 179
A9: 289a8ea6-642e-4b99-8fd3-3636bcfff1d5 | B9: 333a070a-b557-4b2e-af6a-91a96ef7371a | C9: 44980 | D9: 44992 | E9: Design | F9: 3 | G9: 81 | H9: 0 | I9: 44 | J9: USA | K9: Mobile | L9: 1 | M9: =IF(COUNTA(A8:L8)<12,"Missing","OK") -> OK | N9: =IF(ISBLANK(F9),AVERAGE(F$4:F$601),F9:F1004) -> 3 | R9: =IFERROR(__xludf.DUMMYFUNCTION("""COMPUTED_VALUE"""),"Marketing") -> Marketing | S9: =IFERROR(__xludf.DUMMYFUNCTION("""COMPUTED_VALUE"""),2.272549019607843) -> 2.272549
A10: bab505e1-4553-46f6-bc5b-a1f3a7578204 | B10: f695765c-a26f-400a-ba3a-a285ffee86ae | C10: 45281 | D10: 45293 | E10: Business | F10: 3.6 | G10: 57 | H10: 1 | I10: 25 | J10: India | K10: Mobile | L10: 1 | M10: =IF(COUNTA(A9:L9)<12,"Missing","OK") -> OK | N10: =IF(ISBLANK(F10),AVERAGE(F$4:F$601),F10:F1005) -> 3.6
A11: 2ea71ca3-dcc9-4308-aa6a-9dd40e633410 | B11: 1372c380-c140-441c-b635-8066e5d151bc | C11: 45088 | D11: 45100 | E11: Marketing | F11: 0.5 | G11: 11 | H11: 0 | I11: 43 | J11: UK | K11: Mobile | L11: 1 | M11: =IF(COUNTA(A10:L10)<12,"Missing","OK") -> OK | N11: =IF(ISBLANK(F11),AVERAGE(F$4:F$601),F11:F1006) -> 0.5
A12: 6687893e-b67b-44a7-8b91-8a1597d6ac6e | B12: 52d57a77-4a92-44b5-ad65-767a55d591cb | C12: 45068 | D12: 45080 | E12: Marketing | F12: 4.7 | G12: 76 | H12: 1 | I12: 17 | J12: USA | K12: Mobile | L12: 1 | M12: =IF(COUNTA(A11:L11)<12,"Missing","OK") -> OK | N12: =IF(ISBLANK(F12),AVERAGE(F$4:F$601),F12:F1007) -> 4.7
A13: 5209afee-c45c-4646-bc03-aa6b4e728b5c | B13: 88262933-ca7c-4fb9-b1f1-769142d77788 | C13: 44939 | D13: 44951 | E13: Marketing | F13: 4.4 | G13: 49 | H13: 1 | I13: 31 | J13: France | K13: Tablet | L13: 0 | M13: =IF(COUNTA(A12:L12)<12,"Missing","OK") -> OK | N13: =IF(ISBLANK(F13),AVERAGE(F$4:F$601),F13:F1008) -> 4.4
A14: ffa30b8e-fc9b-45d5-beb4-90941141d853 | B14: d2d92ae0-0131-4401-a893-2907767aabdb | C14: 45128 | D14: 45140 | E14: Marketing | F14: 2.6 | G14: 5 | H14: 0 | I14: 35 | J14: India | K14: Tablet | L14: 1 | M14: =IF(COUNTA(A13:L13)<12,"Missing","OK") -> OK | N14: =IF(ISBLANK(F14),AVERAGE(F$4:F$601),F14:F1009) -> 2.6
A15: 373def54-c256-4f5a-8cf5-f57bff0152c2 | B15: 5b3d4dca-0197-4560-a54f-4179c5b0b029 | C15: 45212 | D15: 45224 | E15: Marketing | F15: 0.8 | G15: 2 | H15: 1 | I15: 36 | J15: UK | K15: Desktop | L15: 0 | M15: =IF(COUNTA(A14:L14)<12,"Missing","OK") -> OK | N15: =IF(ISBLANK(F15),AVERAGE(F$4:F$601),F15:F1010) -> 0.8
A16: e5343efa-051f-4846-881b-7c410937b7d1 | B16: 18020988-974c-40b3-94e9-74068bf8d6f2 | C16: 45195 | D16: 45207 | E16: Marketing | F16: 0.1 | G16: 8 | H16: 1 | I16: 15 | J16: Germany | K16: Mobile | L16: 0 | M16: =IF(COUNTA(A15:L15)<12,"Missing","OK") -> OK | N16: =IF(ISBLANK(F16),AVERAGE(F$4:F$601),F16:F1011) -> 0.1
A17: 700982ed-64b8-4640-bc21-47e219c8e6a7 | B17: a285743e-2044-48d1-88c7-2ee8a69e49b2 | C17: 45110 | D17: 45122 | E17: Data Science | F17: 4.5 | G17: 27 | H17: 1 | I17: 46 | J17: Germany | K17: Mobile | L17: 1 | M17: =IF(COUNTA(A16:L16)<12,"Missing","OK") -> OK | N17: =IF(ISBLANK(F17),AVERAGE(F$4:F$601),F17:F1012) -> 4.5
A18: eeae577b-7f01-4a35-8620-b2e4a07ed3f0 | B18: 43b17f71-354e-4e9b-8d66-86182a2ea746 | C18: 44975 | D18: 44987 | E18: Marketing | F18: 3.5 | G18: 48 | H18: 1 | I18: 13 | J18: UK | K18: Mobile | L18: 0 | M18: =IF(COUNTA(A17:L17)<12,"Missing","OK") -> OK | N18: =IF(ISBLANK(F18),AVERAGE(F$4:F$601),F18:F1013) -> 3.5
A19: afe9d25a-0a92-482e-b447-757a7e487596 | B19: 50f8768f-b8f6-44a9-8bb8-a3971705b698 | C19: 45173 | D19: 45185 | E19: Marketing | F19: 4.6 | G19: 15 | H19: 0 | I19: 21 | J19: UK | K19: Tablet | L19: 1 | M19: =IF(COUNTA(A18:L18)<12,"Missing","OK") -> OK | N19: =IF(ISBLANK(F19),AVERAGE(F$4:F$601),F19:F1014) -> 4.6
A20: d9f704d8-a778-4f93-b391-da1abbf7c7f1 | B20: db0f0720-758a-4873-bf46-019ec0db9f93 | C20: 45218 | D20: 45230 | E20: Design | F20: 1.8 | G20: 71 | H20: 0 | I20: 14 | J20: France | K20: Mobile | L20: 1 | M20: =IF(COUNTA(A19:L19)<12,"Missing","OK") -> OK | N20: =IF(ISBLANK(F20),AVERAGE(F$4:F$601),F20:F1015) -> 1.8
A21: 36ee6d3c-95ff-4c64-ac5d-cf0877ba4c3b | B21: 1d8f34d9-3c13-44eb-9c8d-04b41a067c6e | C21: 44961 | D21: 44973 | E21: Marketing | F21: 0 | G21: 28 | H21: 0 | I21: 56 | J21: India | K21: Tablet | L21: 1 | M21: =IF(COUNTA(A20:L20)<12,"Missing","OK") -> OK | N21: =IF(ISBLANK(F21),AVERAGE(F$4:F$601),F21:F1016) -> 0
... A28: 95a75e2f-cedb-4dcd-acaf-9c00752e4b48 | B28: fdcaa6b6-3633-478c-9932-97f50559300b | C28: 44936 | D28: 44948 | E28: Design | F28: 2.9 | G28: 56 | H28: 0 | I28: 50 | J28: Germany | K28: Mobile | L28: 1 | M28: =IF(COUNTA(A27:L27)<12,"Missing","OK") -> OK | N28: =IF(ISBLANK(F28),AVERAGE(F$4:F$601),F28:F1023) -> 2.9
A29: abf5ad77-6b08-4072-99d0-6c3ffc1c99e2 | B29: 6f630d69-66d7-4b3f-92cd-ce83d6a1ce06 | C29: 45176 | D29: 45188 | E29: Design | F29: 1 | G29: 69 | H29: 0 | I29: 19 | J29: France | K29: Desktop | L29: 1 | M29: =IF(COUNTA(A28:L28)<12,"Missing","OK") -> OK | N29: =IF(ISBLANK(F29),AVERAGE(F$4:F$601),F29:F1024) -> 1 | O29: Отже, найвищий середній рейтинг мають Business-курси (2.70), трохи нижчий — Data Science (2.63). Найнижчий рейтинг — у Design-курсів (2.43). Це може свідчити про те, що користувачі більше задоволені практичними бізнес-курсами, ніж творчими напрямами." | U29: Найчастіше студенти навчаються з планшетів (36.7%) та мобільних пристроїв (33.5%), менше — з комп’ютерів (29.8%). Це підкреслює мобільність та адаптивність EdTech-платформи до навчання “на ходу”"
A30: 8268a58c-fb4b-42bf-8b67-32b7e943d134 | B30: 66aa5ddf-1a0a-484c-a00d-3f4d56a7e7b7 | C30: 45071 | D30: 45083 | E30: Data Science | F30: 1.4 | G30: 63 | H30: 0 | I30: 45 | J30: France | K30: Tablet | L30: 1 | M30: =IF(COUNTA(A29:L29)<12,"Missing","OK") -> OK | N30: =IF(ISBLANK(F30),AVERAGE(F$4:F$601),F30:F1025) -> 1.4 | Q30: Топ країни за кількістю студентів | U30: Середній відсоток завершення курсів у кожній категорії
A31: b93f08ee-5d61-4bce-beda-1b6d82ec4d5a | B31: 0571bb4d-3cd7-4d44-88f9-05859805c3f5 | C31: 45250 | D31: 45262 | E31: Design | F31: 1.2 | G31: 82 | H31: 0 | I31: 23 | J31: Germany | K31: Tablet | L31: 1 | M31: =IF(COUNTA(A30:L30)<12,"Missing","OK") -> OK | N31: =IF(ISBLANK(F31),AVERAGE(F$4:F$601),F31:F1026) -> 1.2 | Q31: =IFERROR(__xludf.DUMMYFUNCTION("QUERY(A3:L1000, ""select J, count(A) where J is not null and J <> '0' and J <> '' group by J order by count(A) desc label count(A) 'users'"", 1)"),"country") -> country | R31: =IFERROR(__xludf.DUMMYFUNCTION("""COMPUTED_VALUE"""),"users") -> users | U31: =IFERROR(__xludf.DUMMYFUNCTION("QUERY(A3:L603, ""SELECT E, AVG(H) WHERE E IS NOT NULL GROUP BY E ORDER BY AVG(H) DESC LABEL AVG(H) 'completion_rate (%)'"", 1)"),"course_category") -> course_category | V31: =IFERROR(__xludf.DUMMYFUNCTION("""COMPUTED_VALUE"""),"completion_rate (%)") -> completion_rate (%)
A32: 90a68172-f944-4054-9f2a-17a58a34db0d | B32: ed3adabb-4224-4117-94ce-5194929f5dc4 | C32: 45096 | D32: 45108 | E32: Data Science | F32: 4.3 | G32: 44 | H32: 1 | I32: 49 | J32: UK | K32: Tablet | L32: 0 | M32: =IF(COUNTA(A31:L31)<12,"Missing","OK") -> OK | N32: =IF(ISBLANK(F32),AVERAGE(F$4:F$601),F32:F1027) -> 4.3 | Q32: =IFERROR(__xludf.DUMMYFUNCTION("""COMPUTED_VALUE"""),"USA") -> USA | R32: =IFERROR(__xludf.DUMMYFUNCTION("""COMPUTED_VALUE"""),125.0) -> 125 | U32: =IFERROR(__xludf.DUMMYFUNCTION("""COMPUTED_VALUE"""),"Business") -> Business | V32: =IFERROR(__xludf.DUMMYFUNCTION("""COMPUTED_VALUE"""),0.6312056737588653) -> 0.63120567
A33: 169b1c5b-5707-435d-84b2-d266376407b6 | B33: c46ed6d5-ade6-4f76-9ff1-022102c3e287 | C33: 45230 | D33: 45242 | E33: Design | F33: 2.1 | G33: 23 | H33: 1 | I33: 41 | J33: USA | K33: Desktop | L33: 1 | M33: =IF(COUNTA(A32:L32)<12,"Missing","OK") -> OK | N33: =IF(ISBLANK(F33),AVERAGE(F$4:F$601),F33:F1028) -> 2.1 | Q33: =IFERROR(__xludf.DUMMYFUNCTION("""COMPUTED_VALUE"""),"India") -> India | R33: =IFERROR(__xludf.DUMMYFUNCTION("""COMPUTED_VALUE"""),124.0) -> 124 | U33: =IFERROR(__xludf.DUMMYFUNCTION("""COMPUTED_VALUE"""),"Data Science") -> Data Science | V33: =IFERROR(__xludf.DUMMYFUNCTION("""COMPUTED_VALUE"""),0.5584415584415584) -> 0.55844156
A34: c0bb3a74-e5dc-4bf5-896a-3496066308ca | B34: 24902e0b-e1f4-46d1-9f75-5ba15aa128f8 | C34: 45139 | D34: 45151 | E34: Data Science | F34: 3.4 | G34: 4 | H34: 1 | I34: 29 | J34: Germany | K34: Tablet | L34: 1 | M34: =IF(COUNTA(A33:L33)<12,"Missing","OK") -> OK | N34: =IF(ISBLANK(F34),AVERAGE(F$4:F$601),F34:F1029) -> 3.4 | Q34: =IFERROR(__xludf.DUMMYFUNCTION("""COMPUTED_VALUE"""),"UK") -> UK | R34: =IFERROR(__xludf.DUMMYFUNCTION("""COMPUTED_VALUE"""),123.0) -> 123 | U34: =IFERROR(__xludf.DUMMYFUNCTION("""COMPUTED_VALUE"""),"Marketing") -> Marketing | V34: =IFERROR(__xludf.DUMMYFUNCTION("""COMPUTED_VALUE"""),0.5555555555555556) -> 0.55555556
A35: 0d76aa16-2605-4ad2-9e4b-45b57cbb6187 | B35: b0a0a5ec-b143-41a8-a772-b000ee9c0a32 | C35: 45015 | D35: 45027 | E35: Business | F35: 1.9 | G35: 59 | H35: 0 | I35: 12 | J35: Germany | K35: Desktop | L35: 0 | M35: =IF(COUNTA(A34:L34)<12,"Missing","OK") -> OK | N35: =IF(ISBLANK(F35),AVERAGE(F$4:F$601),F35:F1030) -> 1.9 | Q35: =IFERROR(__xludf.DUMMYFUNCTION("""COMPUTED_VALUE"""),"France") -> France | R35: =IFERROR(__xludf.DUMMYFUNCTION("""COMPUTED_VALUE"""),116.0) -> 116 | U35: =IFERROR(__xludf.DUMMYFUNCTION("""COMPUTED_VALUE"""),"Design") -> Design | V35: =IFERROR(__xludf.DUMMYFUNCTION("""COMPUTED_VALUE"""),0.506578947368421) -> 0.50657895
A36: 4c31e6d4-7d7c-4a3b-85b1-fe33d7385185 | B36: 96a766c7-d8d7-4728-a19d-d3464232eaf9 | C36: 45152 | D36: 45164 | E36: Design | F36: 2.3 | G36: 77 | H36: 1 | I36: 24 | J36: India | K36: Desktop | L36: 1 | M36: =IF(COUNTA(A35:L35)<12,"Missing","OK") -> OK | N36: =IF(ISBLANK(F36),AVERAGE(F$4:F$601),F36:F1031) -> 2.3 | Q36: =IFERROR(__xludf.DUMMYFUNCTION("""COMPUTED_VALUE"""),"Germany") -> Germany | R36: =IFERROR(__xludf.DUMMYFUNCTION("""COMPUTED_VALUE"""),112.0) -> 112
A37: 28cc9682-41da-4cf8-8cbc-2705fe4ccd1f | B37: d9a74708-71ef-4a7e-9304-395e6678b0c1 | C37: 45241 | D37: 45253 | E37: Marketing | F37: 0.4 | G37: 17 | H37: 0 | I37: 22 | J37: France | K37: Tablet | L37: 0 | M37: =IF(COUNTA(A36:L36)<12,"Missing","OK") -> OK | N37: =IF(ISBLANK(F37),AVERAGE(F$4:F$601),F37:F1032) -> 0.4
A38: 0f266902-f574-455f-8e85-6b8622c66d8e | B38: e0371364-ea81-4930-b7d3-39f4749c13dd | C38: 45140 | D38: 45152 | E38: Data Science | F38: 4.2 | G38: 91 | H38: 1 | I38: 27 | J38: UK | K38: Mobile | L38: 1 | M38: =IF(COUNTA(A37:L37)<12,"Missing","OK") -> OK | N38: =IF(ISBLANK(F38),AVERAGE(F$4:F$601),F38:F1033) -> 4.2
A39: 91b42016-c95d-4b81-b083-4b5891d3fe14 | B39: fce3de29-0a78-4854-8211-83e86e09ff08 | C39: 45219 | D39: 45231 | E39: Data Science | F39: 0.7 | G39: 7 | H39: 0 | I39: 52 | J39: USA | K39: Mobile | L39: 1 | M39: =IF(COUNTA(A38:L38)<12,"Missing","OK") -> OK | N39: =IF(ISBLANK(F39),AVERAGE(F$4:F$601),F39:F1034) -> 0.7
A40: 8c08e75a-40ba-4a0f-a0b7-218152b7f01d | B40: 0dfb75cf-59d8-4ac1-b3d1-f783e311da73 | C40: 45163 | D40: 45175 | E40: Business | F40: 1.5 | G40: 50 | H40: 1 | I40: 18 | J40: USA | K40: Desktop | L40: 0 | M40: =IF(COUNTA(A39:L39)<12,"Missing","OK") -> OK | N40: =IF(ISBLANK(F40),AVERAGE(F$4:F$601),F40:F1035) -> 1.5
A41: b5357b2c-8e19-46f2-aa07-5f63fafc2ca6 | B41: 1af6580f-6d75-4252-b454-ae534b20e116 | C41: 45195 | D41: 45207 | E41: Business | F41: 4.8 | G41: 10 | H41: 1 | I41: 54 | J41: France | K41: Tablet | L41: 1 | M41: =IF(COUNTA(A40:L40)<12,"Missing","OK") -> OK | N41: =IF(ISBLANK(F41),AVERAGE(F$4:F$601),F41:F1036) -> 4.8
A42: 2e94b6f5-aaba-4a17-bff9-ae301bf93bcb | B42: deae11e3-0aaa-4f95-af2c-eb958c803657 | C42: 44953 | D42: 44965 | E42: Design | F42: 1.1 | G42: 24 | H42: 0 | I42: 32 | J42: USA | K42: Tablet | L42: 1 | M42: =IF(COUNTA(A41:L41)<12,"Missing","OK") -> OK | N42: =IF(ISBLANK(F42),AVERAGE(F$4:F$601),F42:F1037) -> 1.1
A43: 8e56f251-83cc-4836-9441-1a75b988eb62 | B43: a3857fdb-59af-4adf-bad4-da061c10d6c9 | C43: 44929 | D43: 44941 | E43: Marketing | F43: 0.9 | G43: 1 | H43: 0 | I43: 38 | J43: India | K43: Mobile | L43: 0 | M43: =IF(COUNTA(A42:L42)<12,"Missing","OK") -> OK | N43: =IF(ISBLANK(F43),AVERAGE(F$4:F$601),F43:F1038) -> 0.9
A44: 9ea4df83-7f0a-420b-9366-ac1d6515398c | B44: 48ac7add-5aad-4917-8eda-dd69d5d49900 | C44: 45177 | D44: 45189 | E44: Data Science | F44: 2.5 | G44: 68 | H44: 1 | I44: 20 | J44: France | K44: Mobile | L44: 1 | M44: =IF(COUNTA(A43:L43)<12,"Missing","OK") -> OK | N44: =IF(ISBLANK(F44),AVERAGE(F$4:F$601),F44:F1039) -> 2.5
A45: 7a07a821-c82f-4d09-b859-6fdb24583070 | B45: 87f89f4b-61c2-4e42-8eeb-ce64bb8eb038 | C45: 45205 | D45: 45217 | E45: Design | F45: 1.6 | G45: 41 | H45: 0 | I45: 47 | J45: USA | K45: Mobile | L45: 1 | M45: =IF(COUNTA(A44:L44)<12,"Missing","OK") -> OK | N45: =IF(ISBLANK(F45),AVERAGE(F$4:F$601),F45:F1040) -> 1.6
A46: bf716e65-a53f-4bec-bbd3-1fc1cfda1add | B46: cd32b47c-631d-4eeb-8a19-1c6961c365dd | C46: 44973 | D46: 44985 | E46: Marketing | F46: 3.9 | G46: 87 | H46: 0 | I46: 55 | J46: UK | K46: Tablet | L46: 0 | M46: =IF(COUNTA(A45:L45)<12,"Missing","OK") -> OK | N46: =IF(ISBLANK(F46),AVERAGE(F$4:F$601),F46:F1041) -> 3.9
...

Sheet SQL Queries
A1: SQL-запити для аналізу освітнього проєкту (EdTech Dataset)
A2: Скріншот виконання запиту | B2: SQL-запит | C2: Коментарі, що робить кожен запит
A3: Запит 1.
B4: -- Аналіз середнього рейтингу курсів за категоріями -- Цей запит визначає, які напрямки навчання отримують найвищу оцінку користувачів. -- Важливо для розуміння, які теми приваблюють студентів і мають вищу якість контенту. | C4: Запит розраховує середній рейтинг курсів за кожною навчальною категорією. Найвищий рейтинг мають Business (2.7) та Data Science (2.63), що свідчить про їхню популярність і якість контенту. Ця метрика важлива для визначення напрямків, у які варто інвестувати ресурси та розвивати нові курси.
B5: SELECT
B6: course_category,
B7: ROUND(AVG(course_rating), 2) AS avg_rating,
B8: COUNT(course_id) AS total_courses
B9: FROM `homework-475519.edtech_dataset.courses_data`
B10: GROUP BY course_category
B11: ORDER BY avg_rating DESC;
A16: Запит 2.
B17: -- Аналіз середнього відсотка завершення курсів за країнами -- Цей запит показує, у яких країнах студенти найчастіше доходять до кінця курсу. -- Це важлива метрика залучення користувачів і ефективності контенту. | C17: Запит аналізує середній відсоток завершення курсів у різних країнах серед користувачів, які повністю пройшли навчання. Результати демонструють рівень мотивації студентів та ефективність навчального контенту залежно від регіону. Для бізнесу ця інформація дозволяє визначити, у яких країнах варто інвестувати у локалізацію, рекламу чи партнерства з навчальними центрами.
B18: SELECT
B19: country,
B20: ROUND(AVG(progress_percent), 2) AS avg_completion_percent,
B21: COUNT(DISTINCT student_id) AS total_students
B22: FROM `homework-475519.edtech_dataset.courses_data`
B23: WHERE completed = 1
B24: GROUP BY country
B25: ORDER BY avg_completion_percent DESC
B26: LIMIT 10;
A32: Запит 3.
B33: -- Аналіз розподілу користувачів за типом пристрою -- Запит показує, які пристрої (мобільний, планшет, комп’ютер) студенти використовують найчастіше, -- і скільки годин у середньому вони витрачають на навчання. -- Це допомагає оцінити, як користувачі взаємодіють із платформою та які пристрої потребують оптимізації. | C33: Запит аналізує, з яких пристроїв користувачі найчастіше проходять курси, та скільки годин у середньому вони витрачають на навчання з кожного пристрою. Найчастіше студенти використовують мобільні пристрої та планшети, що свідчить про потребу оптимізації контенту під мобільний формат. Цей аналіз допомагає бізнесу визначити пріоритети для покращення UX-досвіду та розробки мобільних застосунків.
B34: SELECT
B35: device,
B36: COUNT(DISTINCT student_id) AS total_users,
B37: ROUND(AVG(hours_spent), 2) AS avg_hours_spent
B38: FROM `homework-475519.edtech_dataset.courses_data`
B39: GROUP BY device
B40: ORDER BY total_users DESC;
A47: Запит 4.
B48: -- Аналіз утримання користувачів через 30 днів після навчання -- Цей запит визначає, який відсоток студентів залишився активним після 30 днів. -- Retention rate є ключовим показником лояльності користувачів і якості контенту EdTech-платформи. | C48: Запит розраховує частку студентів, які залишились активними через 30 днів після навчання. Цей показник відображає рівень залученості та лояльності користувачів до платформи. Високий retention rate свідчить про якісний контент, корисні курси та ефективну взаємодію з аудиторією. Для бізнесу це один із ключових KPI, що впливає на стабільність доходу та розвиток продукту.
B49: SELECT
B50: ROUND((
B51: SELECT COUNT(DISTINCT student_id)
B52: FROM `homework-475519.edtech_dataset.courses_data`
B53: WHERE retained_after_30d = 1
B54: ) * 100.0 / COUNT(DISTINCT student_id), 2) AS retention_rate_percent
B55: FROM `homework-475519.edtech_dataset.courses_data`;

Sheet Dashboard
D1: АНАЛІТИЧНИЙ ЗВІТ ПО ОСВІТНІЙ ПЛАТФОРМІ
C3: Загальна кількість студентів | F3: Кількість завершених курсів | I3: Середній рейтинг курсів | L3: Середня кількість годин навчання
C4: =IFERROR(__xludf.DUMMYFUNCTION("COUNTUNIQUE('Raw Data'!A2:A1000)"),600.0) -> 600 | F4: =COUNTIF('Raw Data'!H2:H601,1) -> 337 | I4: =AVERAGE('Raw Data'!F2:F601) -> 2.505 | L4: =AVERAGE('Raw Data'!I2:I601) -> 34.086667
C6: Частка студентів, які залишилися активними через 30 днів | F6: Частка завершених курсів | I6: Середній відсоток завершення курсів | L6: Найпопулярніший пристрій
C7: =ROUND(COUNTIF('Raw Data'!L2:L601,1)/COUNTA('Raw Data'!L2:L601),2) -> 0.67 | F7: =COUNTIF('Raw Data'!H2:H601,1)/COUNTA('Raw Data'!H2:H601) -> 0.56166667 | I7: =AVERAGE('Raw Data'!G2:G601)/100 -> 0.499399 | L7: {=INDEX(UNIQUE('Raw Data'!K2:K601),MATCH(MAX(COUNTIF('Raw Data'!K2:K601,UNIQUE('Raw Data'!K2:K601))),COUNTIF('Raw Data'!K2:K601,UNIQUE('Raw Data'!K2:K601)),0))} -> Tablet
B9: {=EDA!R4:S9} -> Середній рейтинг курсів за категоріями | I9: {=EDA!U30:V35} -> Середній відсоток завершення курсів у кожній категорії | L9: Кількість країн, з яких зареєстровані студенти на платформі
B10: course_category | C10: avg_rating | I10: course_category | J10: completion_rate (%) | L10: =IFERROR(__xludf.DUMMYFUNCTION("COUNTUNIQUE('Raw Data'!J2:J601)"),5.0) -> 5
B11: Business | C11: 2.6985816 | I11: Business | J11: 0.63120567
B12: Data Science | C12: 2.6318182 | I12: Data Science | J12: 0.55844156
B13: Design | C13: 2.4309211 | I13: Marketing | J13: 0.55555556
B14: Marketing | C14: 2.272549 | I14: Design | J14: 0.50657895
B16: {=EDA!Q30:R36} -> Топ країни за кількістю студентів
B17: country | C17: users
B18: USA | C18: 125
B19: India | C19: 124
B20: UK | C20: 123
B21: France | C21: 116
B22: Germany | C22: 112
F23: {=EDA!U4:V8} -> Розподіл користувачів за пристроями
F24: device | G24: users
F25: Tablet | G25: 220
F26: Mobile | G26: 201
F27: Desktop | G27: 179
J29: Взаємозв’язок між середнім рейтингом курсу та середнім відсотком завершення

Sheet Conclusions
C1: Підсумкові висновки за результатами аналізу освітньої платформи
A2: У таблиці були перевірені типи даних, відсутність дублікатів і порожніх значень. Дані приведено до єдиного формату (дати, числові показники).
A3: Виконано перевірку на пропуски — результат “OK” для всіх стовпців, що підтверджує якість вихідних даних.
A5: 1. Загальні показники активності
A6: Платформа має стабільну базу користувачів — 600 студентів, з яких 67% залишаються активними через 30 днів після початку навчання.
A7: Середня кількість годин, витрачених студентами на навчання, становить 34.09 годин.
A8: Висновок:
A9: Це свідчить про високий рівень лояльності, інтерес до контенту та ефективність комунікаційних стратегій.
A10: Рекомендації:
A11: Підтримувати регулярну комунікацію зі студентами через листи, повідомлення та push-сповіщення.
A12: Впровадити мотиваційні програми, бейджі, сертифікати або бонуси для підвищення Retention Rate.
A13: Регулярно доповнювати базу новими полями — наприклад, часом перегляду відео або кількістю спроб тестів.
A14: 2. Рівень завершення курсів
... A67: На основі даних формувати персоналізовані рекомендації для користувачів (наприклад, “схожі курси” або “наступний крок у навчанні”).
